Workbook
Name age: #REF!
Name count: #REF!
Name worth: #REF!

Sheet Starting Data
B2: Date | C2: Month | D2: Amount | E2: Type | F2: Income/ Expense | G2: Description (optional) | I2: Type | J2: Income / Expense
B3: 2026-01-01 | D3: 3282 | E3: Salary | G3: Monthly salary | I3: Salary | J3: Income
B4: 2026-01-02 | D4: 608 | E4: Side Hustle | G4: Side project income | I4: Side Hustle | J4: Income
B5: 2026-01-03 | D5: 130 | E5: Interest / Dividends | G5: Investment income | I5: Interest / Dividends | J5: Income
B6: 2026-01-04 | D6: 24 | E6: Gifts / Other | G6: Gifts or irregular income | I6: Gifts / Other | J6: Income
B7: 2026-01-05 | D7: 1100 | E7: Rent / Mortgage | G7: Monthly rent or mortgage | I7: Rent / Mortgage | J7: Expense
B8: 2026-01-06 | D8: 129 | E8: Utilities | G8: Electricity, water, internet | I8: Utilities | J8: Expense
B9: 2026-01-07 | D9: 840 | E9: Property Tax | G9: Property tax payment | I9: Property Tax | J9: Expense
B10: 2026-01-08 | D10: 217 | E10: Household Goods | G10: Home supplies | I10: Household Goods | J10: Expense
B11: 2026-01-09 | D11: 420 | E11: Car Payment | G11: Car loan payment | I11: Car Payment | J11: Expense
B12: 2026-01-10 | D12: 102 | E12: Fuel | G12: Fuel costs | I12: Fuel | J12: Expense
B13: 2026-01-11 | D13: 83 | E13: Public Transport | G13: Public transport | I13: Public Transport | J13: Expense
B14: 2026-01-12 | D14: 94 | E14: Taxis & Other | G14: Ride sharing & taxis | I14: Taxis & Other | J14: Expense
... B23: 2026-01-21 | D23: 121 | E23: Other Expenses | G23: Miscellaneous | I23: Other Expenses | J23: Expense
B24: 2026-02-01 | D24: 3223 | E24: Salary | G24: Monthly salary
B25: 2026-02-02 | D25: 1169 | E25: Side Hustle | G25: Side project income
B26: 2026-02-03 | D26: 87 | E26: Interest / Dividends | G26: Investment income
B27: 2026-02-04 | D27: 289 | E27: Gifts / Other | G27: Gifts or irregular income
B28: 2026-02-05 | D28: 1100 | E28: Rent / Mortgage | G28: Monthly rent or mortgage
B29: 2026-02-06 | D29: 135 | E29: Utilities | G29: Electricity, water, internet
B30: 2026-02-07 | D30: 228 | E30: Property Tax | G30: Property tax payment
B31: 2026-02-08 | D31: 240 | E31: Household Goods | G31: Home supplies
B32: 2026-02-09 | D32: 420 | E32: Car Payment | G32: Car loan payment
B33: 2026-02-10 | D33: 164 | E33: Fuel | G33: Fuel costs
B34: 2026-02-11 | D34: 63 | E34: Public Transport | G34: Public transport
B35: 2026-02-12 | D35: 93 | E35: Taxis & Other | G35: Ride sharing & taxis
... B254: 2026-12-21 | D254: 86 | E254: Other Expenses | G254: Miscellaneous

Sheet Ending Data
B2: Date | C2: Month | D2: Amount | E2: Type | F2: Income/ Expense | G2: Description (optional) | I2: Type | J2: Income / Expense
B3: 2026-01-01 | C3: =TEXT(B3,"mmm") -> Jan | D3: 3282 | E3: Salary | F3: =_xlfn.XLOOKUP(Table1[[#This Row],[Type]],Table2[Type],Table2[Income / Expense]) -> Income | G3: Monthly salary | I3: Salary | J3: Income
B4: 2026-01-02 | C4: =TEXT(B4,"mmm") -> Jan | D4: 608 | E4: Side Hustle | F4: =_xlfn.XLOOKUP(Table1[[#This Row],[Type]],Table2[Type],Table2[Income / Expense]) -> Income | G4: Side project income | I4: Side Hustle | J4: Income
B5: 2026-01-03 | C5: =TEXT(B5,"mmm") -> Jan | D5: 130 | E5: Interest / Dividends | F5: =_xlfn.XLOOKUP(Table1[[#This Row],[Type]],Table2[Type],Table2[Income / Expense]) -> Income | G5: Investment income | I5: Interest / Dividends | J5: Income
B6: 2026-01-04 | C6: =TEXT(B6,"mmm") -> Jan | D6: 24 | E6: Gifts / Other | F6: =_xlfn.XLOOKUP(Table1[[#This Row],[Type]],Table2[Type],Table2[Income / Expense]) -> Income | G6: Gifts or irregular income | I6: Gifts / Other | J6: Income
B7: 2026-01-05 | C7: =TEXT(B7,"mmm") -> Jan | D7: 1100 | E7: Rent / Mortgage | F7: =_xlfn.XLOOKUP(Table1[[#This Row],[Type]],Table2[Type],Table2[Income / Expense]) -> Expense | G7: Monthly rent or mortgage | I7: Rent / Mortgage | J7: Expense
B8: 2026-01-06 | C8: =TEXT(B8,"mmm") -> Jan | D8: 129 | E8: Utilities | F8: =_xlfn.XLOOKUP(Table1[[#This Row],[Type]],Table2[Type],Table2[Income / Expense]) -> Expense | G8: Electricity, water, internet | I8: Utilities | J8: Expense
B9: 2026-01-07 | C9: =TEXT(B9,"mmm") -> Jan | D9: 840 | E9: Property Tax | F9: =_xlfn.XLOOKUP(Table1[[#This Row],[Type]],Table2[Type],Table2[Income / Expense]) -> Expense | G9: Property tax payment | I9: Property Tax | J9: Expense
B10: 2026-01-08 | C10: =TEXT(B10,"mmm") -> Jan | D10: 217 | E10: Household Goods | F10: =_xlfn.XLOOKUP(Table1[[#This Row],[Type]],Table2[Type],Table2[Income / Expense]) -> Expense | G10: Home supplies | I10: Household Goods | J10: Expense
B11: 2026-01-09 | C11: =TEXT(B11,"mmm") -> Jan | D11: 420 | E11: Car Payment | F11: =_xlfn.XLOOKUP(Table1[[#This Row],[Type]],Table2[Type],Table2[Income / Expense]) -> Expense | G11: Car loan payment | I11: Car Payment | J11: Expense
B12: 2026-01-10 | C12: =TEXT(B12,"mmm") -> Jan | D12: 102 | E12: Fuel | F12: =_xlfn.XLOOKUP(Table1[[#This Row],[Type]],Table2[Type],Table2[Income / Expense]) -> Expense | G12: Fuel costs | I12: Fuel | J12: Expense
B13: 2026-01-11 | C13: =TEXT(B13,"mmm") -> Jan | D13: 83 | E13: Public Transport | F13: =_xlfn.XLOOKUP(Table1[[#This Row],[Type]],Table2[Type],Table2[Income / Expense]) -> Expense | G13: Public transport | I13: Public Transport | J13: Expense
B14: 2026-01-12 | C14: =TEXT(B14,"mmm") -> Jan | D14: 94 | E14: Taxis & Other | F14: =_xlfn.XLOOKUP(Table1[[#This Row],[Type]],Table2[Type],Table2[Income / Expense]) -> Expense | G14: Ride sharing & taxis | I14: Taxis & Other | J14: Expense
... B23: 2026-01-21 | C23: =TEXT(B23,"mmm") -> Jan | D23: 121 | E23: Other Expenses | F23: =_xlfn.XLOOKUP(Table1[[#This Row],[Type]],Table2[Type],Table2[Income / Expense]) -> Expense | G23: Miscellaneous | I23: Other Expenses | J23: Expense
B24: 2026-02-01 | C24: =TEXT(B24,"mmm") -> Feb | D24: 3223 | E24: Salary | F24: =_xlfn.XLOOKUP(Table1[[#This Row],[Type]],Table2[Type],Table2[Income / Expense]) -> Income | G24: Monthly salary
B25: 2026-02-02 | C25: =TEXT(B25,"mmm") -> Feb | D25: 1169 | E25: Side Hustle | F25: =_xlfn.XLOOKUP(Table1[[#This Row],[Type]],Table2[Type],Table2[Income / Expense]) -> Income | G25: Side project income
B26: 2026-02-03 | C26: =TEXT(B26,"mmm") -> Feb | D26: 87 | E26: Interest / Dividends | F26: =_xlfn.XLOOKUP(Table1[[#This Row],[Type]],Table2[Type],Table2[Income / Expense]) -> Income | G26: Investment income
B27: 2026-02-04 | C27: =TEXT(B27,"mmm") -> Feb | D27: 289 | E27: Gifts / Other | F27: =_xlfn.XLOOKUP(Table1[[#This Row],[Type]],Table2[Type],Table2[Income / Expense]) -> Income | G27: Gifts or irregular income
B28: 2026-02-05 | C28: =TEXT(B28,"mmm") -> Feb | D28: 1100 | E28: Rent / Mortgage | F28: =_xlfn.XLOOKUP(Table1[[#This Row],[Type]],Table2[Type],Table2[Income / Expense]) -> Expense | G28: Monthly rent or mortgage
B29: 2026-02-06 | C29: =TEXT(B29,"mmm") -> Feb | D29: 135 | E29: Utilities | F29: =_xlfn.XLOOKUP(Table1[[#This Row],[Type]],Table2[Type],Table2[Income / Expense]) -> Expense | G29: Electricity, water, internet
B30: 2026-02-07 | C30: =TEXT(B30,"mmm") -> Feb | D30: 228 | E30: Property Tax | F30: =_xlfn.XLOOKUP(Table1[[#This Row],[Type]],Table2[Type],Table2[Income / Expense]) -> Expense | G30: Property tax payment
B31: 2026-02-08 | C31: =TEXT(B31,"mmm") -> Feb | D31: 240 | E31: Household Goods | F31: =_xlfn.XLOOKUP(Table1[[#This Row],[Type]],Table2[Type],Table2[Income / Expense]) -> Expense | G31: Home supplies
B32: 2026-02-09 | C32: =TEXT(B32,"mmm") -> Feb | D32: 420 | E32: Car Payment | F32: =_xlfn.XLOOKUP(Table1[[#This Row],[Type]],Table2[Type],Table2[Income / Expense]) -> Expense | G32: Car loan payment
B33: 2026-02-10 | C33: =TEXT(B33,"mmm") -> Feb | D33: 164 | E33: Fuel | F33: =_xlfn.XLOOKUP(Table1[[#This Row],[Type]],Table2[Type],Table2[Income / Expense]) -> Expense | G33: Fuel costs
B34: 2026-02-11 | C34: =TEXT(B34,"mmm") -> Feb | D34: 63 | E34: Public Transport | F34: =_xlfn.XLOOKUP(Table1[[#This Row],[Type]],Table2[Type],Table2[Income / Expense]) -> Expense | G34: Public transport
B35: 2026-02-12 | C35: =TEXT(B35,"mmm") -> Feb | D35: 93 | E35: Taxis & Other | F35: =_xlfn.XLOOKUP(Table1[[#This Row],[Type]],Table2[Type],Table2[Income / Expense]) -> Expense | G35: Ride sharing & taxis
... B254: 2026-12-21 | C254: =TEXT(B254,"mmm") -> Dec | D254: 86 | E254: Other Expenses | F254: =_xlfn.XLOOKUP(Table1[[#This Row],[Type]],Table2[Type],Table2[Income / Expense]) -> Expense | G254: Miscellaneous

Sheet KPIs
B11: Income
B12: Salary
B13: Side Hustle
B14: Interest / Dividends
B15: Gifts / Other
B18: Expenses: Home
B19: Rent / Mortgage
B20: Utilities
B21: Property Tax
B22: Household Goods
B25: Expenses: Transport
B26: Car Payment
... B46: Total Expenses

Sheet Final Result
B1: Personal Finance Tracker
B4: YTD Income | C4: =O15 -> 57528
B5: YTD Expenses | C5: =O45 -> 53833
B6: YTD Savings | C6: =C4-C5 -> 3695
B7: Cumulative Savings | C7: =N50 -> 13695
B10: Income | C10: JAN | D10: FEB | E10: MAR | F10: APR | G10: MAY | H10: JUN | I10: JUL | J10: AUG | K10: SEP | L10: OCT | M10: NOV | N10: DEC | O10: Total | P10: Avg
B11: Salary | C11: =SUMIFS(Table1[Amount],Table1[Type],'Final Result'!$B11,Table1[Month],'Final Result'!C$10) -> 3282 | D11: =SUMIFS(Table1[Amount],Table1[Type],'Final Result'!$B11,Table1[Month],'Final Result'!D$10) -> 3223 | E11: =SUMIFS(Table1[Amount],Table1[Type],'Final Result'!$B11,Table1[Month],'Final Result'!E$10) -> 3236 | F11: =SUMIFS(Table1[Amount],Table1[Type],'Final Result'!$B11,Table1[Month],'Final Result'!F$10) -> 3358 | G11: =SUMIFS(Table1[Amount],Table1[Type],'Final Result'!$B11,Table1[Month],'Final Result'!G$10) -> 3334 | H11: =SUMIFS(Table1[Amount],Table1[Type],'Final Result'!$B11,Table1[Month],'Final Result'!H$10) -> 3845 | I11: =SUMIFS(Table1[Amount],Table1[Type],'Final Result'!$B11,Table1[Month],'Final Result'!I$10) -> 3848 | J11: =SUMIFS(Table1[Amount],Table1[Type],'Final Result'!$B11,Table1[Month],'Final Result'!J$10) -> 3848 | ... N11: =SUMIFS(Table1[Amount],Table1[Type],'Final Result'!$B11,Table1[Month],'Final Result'!N$10) -> 3848 | O11: =SUM(C11:N11) -> 43366 | P11: =SUM(D11:O11) -> 83450
B12: Side Hustle | C12: =SUMIFS(Table1[Amount],Table1[Type],'Final Result'!$B12,Table1[Month],'Final Result'!C$10) -> 608 | D12: =SUMIFS(Table1[Amount],Table1[Type],'Final Result'!$B12,Table1[Month],'Final Result'!D$10) -> 1169 | E12: =SUMIFS(Table1[Amount],Table1[Type],'Final Result'!$B12,Table1[Month],'Final Result'!E$10) -> 541 | F12: =SUMIFS(Table1[Amount],Table1[Type],'Final Result'!$B12,Table1[Month],'Final Result'!F$10) -> 721 | G12: =SUMIFS(Table1[Amount],Table1[Type],'Final Result'!$B12,Table1[Month],'Final Result'!G$10) -> 1313 | H12: =SUMIFS(Table1[Amount],Table1[Type],'Final Result'!$B12,Table1[Month],'Final Result'!H$10) -> 942 | I12: =SUMIFS(Table1[Amount],Table1[Type],'Final Result'!$B12,Table1[Month],'Final Result'!I$10) -> 882 | J12: =SUMIFS(Table1[Amount],Table1[Type],'Final Result'!$B12,Table1[Month],'Final Result'!J$10) -> 1316 | ... N12: =SUMIFS(Table1[Amount],Table1[Type],'Final Result'!$B12,Table1[Month],'Final Result'!N$10) -> 1070 | O12: =SUM(C12:N12) -> 10710 | P12: =SUM(D12:O12) -> 20812
B13: Interest / Dividends | C13: =SUMIFS(Table1[Amount],Table1[Type],'Final Result'!$B13,Table1[Month],'Final Result'!C$10) -> 130 | D13: =SUMIFS(Table1[Amount],Table1[Type],'Final Result'!$B13,Table1[Month],'Final Result'!D$10) -> 87 | E13: =SUMIFS(Table1[Amount],Table1[Type],'Final Result'!$B13,Table1[Month],'Final Result'!E$10) -> 153 | F13: =SUMIFS(Table1[Amount],Table1[Type],'Final Result'!$B13,Table1[Month],'Final Result'!F$10) -> 143 | G13: =SUMIFS(Table1[Amount],Table1[Type],'Final Result'!$B13,Table1[Month],'Final Result'!G$10) -> 192 | H13: =SUMIFS(Table1[Amount],Table1[Type],'Final Result'!$B13,Table1[Month],'Final Result'!H$10) -> 123 | I13: =SUMIFS(Table1[Amount],Table1[Type],'Final Result'!$B13,Table1[Month],'Final Result'!I$10) -> 171 | J13: =SUMIFS(Table1[Amount],Table1[Type],'Final Result'!$B13,Table1[Month],'Final Result'!J$10) -> 90 | ... N13: =SUMIFS(Table1[Amount],Table1[Type],'Final Result'!$B13,Table1[Month],'Final Result'!N$10) -> 99 | O13: =SUM(C13:N13) -> 1522 | P13: =SUM(D13:O13) -> 2914
B14: Gifts / Other | C14: =SUMIFS(Table1[Amount],Table1[Type],'Final Result'!$B14,Table1[Month],'Final Result'!C$10) -> 24 | D14: =SUMIFS(Table1[Amount],Table1[Type],'Final Result'!$B14,Table1[Month],'Final Result'!D$10) -> 289 | E14: =SUMIFS(Table1[Amount],Table1[Type],'Final Result'!$B14,Table1[Month],'Final Result'!E$10) -> 157 | F14: =SUMIFS(Table1[Amount],Table1[Type],'Final Result'!$B14,Table1[Month],'Final Result'!F$10) -> 272 | G14: =SUMIFS(Table1[Amount],Table1[Type],'Final Result'!$B14,Table1[Month],'Final Result'!G$10) -> 175 | H14: =SUMIFS(Table1[Amount],Table1[Type],'Final Result'!$B14,Table1[Month],'Final Result'!H$10) -> 179 | I14: =SUMIFS(Table1[Amount],Table1[Type],'Final Result'!$B14,Table1[Month],'Final Result'!I$10) -> 197 | J14: =SUMIFS(Table1[Amount],Table1[Type],'Final Result'!$B14,Table1[Month],'Final Result'!J$10) -> 85 | ... N14: =SUMIFS(Table1[Amount],Table1[Type],'Final Result'!$B14,Table1[Month],'Final Result'!N$10) -> 129 | O14: =SUM(C14:N14) -> 1930 | P14: =SUM(D14:O14) -> 3836
B15: Total Income | C15: =SUM(C11:C14) -> 4044 | D15: =SUM(D11:D14) -> 4768 | E15: =SUM(E11:E14) -> 4087 | F15: =SUM(F11:F14) -> 4494 | G15: =SUM(G11:G14) -> 5014 | H15: =SUM(H11:H14) -> 5089 | I15: =SUM(I11:I14) -> 5098 | J15: =SUM(J11:J14) -> 5339 | ... P15: =SUM(P11:P14) -> 111012
B17: Expenses: Home | O17: Total | P17: Avg
B18: Rent / Mortgage | C18: =SUMIFS(Table1[Amount],Table1[Type],'Final Result'!$B18,Table1[Month],'Final Result'!C$10) -> 1100 | D18: =SUMIFS(Table1[Amount],Table1[Type],'Final Result'!$B18,Table1[Month],'Final Result'!D$10) -> 1100 | E18: =SUMIFS(Table1[Amount],Table1[Type],'Final Result'!$B18,Table1[Month],'Final Result'!E$10) -> 1100 | F18: =SUMIFS(Table1[Amount],Table1[Type],'Final Result'!$B18,Table1[Month],'Final Result'!F$10) -> 1100 | G18: =SUMIFS(Table1[Amount],Table1[Type],'Final Result'!$B18,Table1[Month],'Final Result'!G$10) -> 1100 | H18: =SUMIFS(Table1[Amount],Table1[Type],'Final Result'!$B18,Table1[Month],'Final Result'!H$10) -> 1100 | I18: =SUMIFS(Table1[Amount],Table1[Type],'Final Result'!$B18,Table1[Month],'Final Result'!I$10) -> 1100 | J18: =SUMIFS(Table1[Amount],Table1[Type],'Final Result'!$B18,Table1[Month],'Final Result'!J$10) -> 1100 | ... N18: =SUMIFS(Table1[Amount],Table1[Type],'Final Result'!$B18,Table1[Month],'Final Result'!N$10) -> 1100 | O18: =SUM(C18:N18) -> 13200 | P18: =SUM(D18:O18) -> 25300
B19: Utilities | C19: =SUMIFS(Table1[Amount],Table1[Type],'Final Result'!$B19,Table1[Month],'Final Result'!C$10) -> 129 | D19: =SUMIFS(Table1[Amount],Table1[Type],'Final Result'!$B19,Table1[Month],'Final Result'!D$10) -> 135 | E19: =SUMIFS(Table1[Amount],Table1[Type],'Final Result'!$B19,Table1[Month],'Final Result'!E$10) -> 191 | F19: =SUMIFS(Table1[Amount],Table1[Type],'Final Result'!$B19,Table1[Month],'Final Result'!F$10) -> 174 | G19: =SUMIFS(Table1[Amount],Table1[Type],'Final Result'!$B19,Table1[Month],'Final Result'!G$10) -> 177 | H19: =SUMIFS(Table1[Amount],Table1[Type],'Final Result'!$B19,Table1[Month],'Final Result'!H$10) -> 196 | I19: =SUMIFS(Table1[Amount],Table1[Type],'Final Result'!$B19,Table1[Month],'Final Result'!I$10) -> 164 | J19: =SUMIFS(Table1[Amount],Table1[Type],'Final Result'!$B19,Table1[Month],'Final Result'!J$10) -> 177 | ... N19: =SUMIFS(Table1[Amount],Table1[Type],'Final Result'!$B19,Table1[Month],'Final Result'!N$10) -> 164 | O19: =SUM(C19:N19) -> 1989 | P19: =SUM(D19:O19) -> 3849
B20: Property Tax | C20: =SUMIFS(Table1[Amount],Table1[Type],'Final Result'!$B20,Table1[Month],'Final Result'!C$10) -> 840 | D20: =SUMIFS(Table1[Amount],Table1[Type],'Final Result'!$B20,Table1[Month],'Final Result'!D$10) -> 228 | E20: =SUMIFS(Table1[Amount],Table1[Type],'Final Result'!$B20,Table1[Month],'Final Result'!E$10) -> 835 | F20: =SUMIFS(Table1[Amount],Table1[Type],'Final Result'!$B20,Table1[Month],'Final Result'!F$10) -> 795 | G20: =SUMIFS(Table1[Amount],Table1[Type],'Final Result'!$B20,Table1[Month],'Final Result'!G$10) -> 294 | H20: =SUMIFS(Table1[Amount],Table1[Type],'Final Result'!$B20,Table1[Month],'Final Result'!H$10) -> 508 | I20: =SUMIFS(Table1[Amount],Table1[Type],'Final Result'!$B20,Table1[Month],'Final Result'!I$10) -> 23 | J20: =SUMIFS(Table1[Amount],Table1[Type],'Final Result'!$B20,Table1[Month],'Final Result'!J$10) -> 411 | ... N20: =SUMIFS(Table1[Amount],Table1[Type],'Final Result'!$B20,Table1[Month],'Final Result'!N$10) -> 616 | O20: =SUM(C20:N20) -> 6242 | P20: =SUM(D20:O20) -> 11644
B21: Household Goods | C21: =SUMIFS(Table1[Amount],Table1[Type],'Final Result'!$B21,Table1[Month],'Final Result'!C$10) -> 217 | D21: =SUMIFS(Table1[Amount],Table1[Type],'Final Result'!$B21,Table1[Month],'Final Result'!D$10) -> 240 | E21: =SUMIFS(Table1[Amount],Table1[Type],'Final Result'!$B21,Table1[Month],'Final Result'!E$10) -> 126 | F21: =SUMIFS(Table1[Amount],Table1[Type],'Final Result'!$B21,Table1[Month],'Final Result'!F$10) -> 160 | G21: =SUMIFS(Table1[Amount],Table1[Type],'Final Result'!$B21,Table1[Month],'Final Result'!G$10) -> 235 | H21: =SUMIFS(Table1[Amount],Table1[Type],'Final Result'!$B21,Table1[Month],'Final Result'!H$10) -> 228 | I21: =SUMIFS(Table1[Amount],Table1[Type],'Final Result'!$B21,Table1[Month],'Final Result'!I$10) -> 198 | J21: =SUMIFS(Table1[Amount],Table1[Type],'Final Result'!$B21,Table1[Month],'Final Result'!J$10) -> 220 | ... N21: =SUMIFS(Table1[Amount],Table1[Type],'Final Result'!$B21,Table1[Month],'Final Result'!N$10) -> 173 | O21: =SUM(C21:N21) -> 2262 | P21: =SUM(D21:O21) -> 4307
B22: Total Home | C22: =SUM(C18:C21) -> 2286 | D22: =SUM(D18:D21) -> 1703 | E22: =SUM(E18:E21) -> 2252 | F22: =SUM(F18:F21) -> 2229 | G22: =SUM(G18:G21) -> 1806 | H22: =SUM(H18:H21) -> 2032 | I22: =SUM(I18:I21) -> 1485 | J22: =SUM(J18:J21) -> 1908 | ... P22: =SUM(P18:P21) -> 45100
B24: Expenses: Transport | O24: Total | P24: Avg
B25: Car Payment | C25: =SUMIFS(Table1[Amount],Table1[Type],'Final Result'!$B25,Table1[Month],'Final Result'!C$10) -> 420 | D25: =SUMIFS(Table1[Amount],Table1[Type],'Final Result'!$B25,Table1[Month],'Final Result'!D$10) -> 420 | E25: =SUMIFS(Table1[Amount],Table1[Type],'Final Result'!$B25,Table1[Month],'Final Result'!E$10) -> 420 | F25: =SUMIFS(Table1[Amount],Table1[Type],'Final Result'!$B25,Table1[Month],'Final Result'!F$10) -> 420 | G25: =SUMIFS(Table1[Amount],Table1[Type],'Final Result'!$B25,Table1[Month],'Final Result'!G$10) -> 420 | H25: =SUMIFS(Table1[Amount],Table1[Type],'Final Result'!$B25,Table1[Month],'Final Result'!H$10) -> 420 | I25: =SUMIFS(Table1[Amount],Table1[Type],'Final Result'!$B25,Table1[Month],'Final Result'!I$10) -> 420 | J25: =SUMIFS(Table1[Amount],Table1[Type],'Final Result'!$B25,Table1[Month],'Final Result'!J$10) -> 420 | ... N25: =SUMIFS(Table1[Amount],Table1[Type],'Final Result'!$B25,Table1[Month],'Final Result'!N$10) -> 420 | O25: =SUM(C25:N25) -> 5040 | P25: =AVERAGE(C25:N25) -> 420
B26: Fuel | C26: =SUMIFS(Table1[Amount],Table1[Type],'Final Result'!$B26,Table1[Month],'Final Result'!C$10) -> 102 | D26: =SUMIFS(Table1[Amount],Table1[Type],'Final Result'!$B26,Table1[Month],'Final Result'!D$10) -> 164 | E26: =SUMIFS(Table1[Amount],Table1[Type],'Final Result'!$B26,Table1[Month],'Final Result'!E$10) -> 103 | F26: =SUMIFS(Table1[Amount],Table1[Type],'Final Result'!$B26,Table1[Month],'Final Result'!F$10) -> 149 | G26: =SUMIFS(Table1[Amount],Table1[Type],'Final Result'!$B26,Table1[Month],'Final Result'!G$10) -> 99 | H26: =SUMIFS(Table1[Amount],Table1[Type],'Final Result'!$B26,Table1[Month],'Final Result'!H$10) -> 148 | I26: =SUMIFS(Table1[Amount],Table1[Type],'Final Result'!$B26,Table1[Month],'Final Result'!I$10) -> 135 | J26: =SUMIFS(Table1[Amount],Table1[Type],'Final Result'!$B26,Table1[Month],'Final Result'!J$10) -> 125 | ... N26: =SUMIFS(Table1[Amount],Table1[Type],'Final Result'!$B26,Table1[Month],'Final Result'!N$10) -> 150 | O26: =SUM(C26:N26) -> 1510 | P26: =AVERAGE(C26:N26) -> 125.83333
B27: Public Transport | C27: =SUMIFS(Table1[Amount],Table1[Type],'Final Result'!$B27,Table1[Month],'Final Result'!C$10) -> 83 | D27: =SUMIFS(Table1[Amount],Table1[Type],'Final Result'!$B27,Table1[Month],'Final Result'!D$10) -> 63 | E27: =SUMIFS(Table1[Amount],Table1[Type],'Final Result'!$B27,Table1[Month],'Final Result'!E$10) -> 97 | F27: =SUMIFS(Table1[Amount],Table1[Type],'Final Result'!$B27,Table1[Month],'Final Result'!F$10) -> 97 | G27: =SUMIFS(Table1[Amount],Table1[Type],'Final Result'!$B27,Table1[Month],'Final Result'!G$10) -> 67 | H27: =SUMIFS(Table1[Amount],Table1[Type],'Final Result'!$B27,Table1[Month],'Final Result'!H$10) -> 64 | I27: =SUMIFS(Table1[Amount],Table1[Type],'Final Result'!$B27,Table1[Month],'Final Result'!I$10) -> 70 | J27: =SUMIFS(Table1[Amount],Table1[Type],'Final Result'!$B27,Table1[Month],'Final Result'!J$10) -> 68 | ... N27: =SUMIFS(Table1[Amount],Table1[Type],'Final Result'!$B27,Table1[Month],'Final Result'!N$10) -> 67 | O27: =SUM(C27:N27) -> 928 | P27: =AVERAGE(C27:N27) -> 77.333333
B28: Taxis & Other | C28: =SUMIFS(Table1[Amount],Table1[Type],'Final Result'!$B28,Table1[Month],'Final Result'!C$10) -> 94 | D28: =SUMIFS(Table1[Amount],Table1[Type],'Final Result'!$B28,Table1[Month],'Final Result'!D$10) -> 93 | E28: =SUMIFS(Table1[Amount],Table1[Type],'Final Result'!$B28,Table1[Month],'Final Result'!E$10) -> 93 | F28: =SUMIFS(Table1[Amount],Table1[Type],'Final Result'!$B28,Table1[Month],'Final Result'!F$10) -> 78 | G28: =SUMIFS(Table1[Amount],Table1[Type],'Final Result'!$B28,Table1[Month],'Final Result'!G$10) -> 85 | H28: =SUMIFS(Table1[Amount],Table1[Type],'Final Result'!$B28,Table1[Month],'Final Result'!H$10) -> 31 | I28: =SUMIFS(Table1[Amount],Table1[Type],'Final Result'!$B28,Table1[Month],'Final Result'!I$10) -> 98 | J28: =SUMIFS(Table1[Amount],Table1[Type],'Final Result'!$B28,Table1[Month],'Final Result'!J$10) -> 75 | ... N28: =SUMIFS(Table1[Amount],Table1[Type],'Final Result'!$B28,Table1[Month],'Final Result'!N$10) -> 34 | O28: =SUM(C28:N28) -> 866 | P28: =AVERAGE(C28:N28) -> 72.166667
B29: Total Transport | C29: =SUM(C25:C28) -> 699 | D29: =SUM(D25:D28) -> 740 | E29: =SUM(E25:E28) -> 713 | F29: =SUM(F25:F28) -> 744 | G29: =SUM(G25:G28) -> 671 | H29: =SUM(H25:H28) -> 663 | I29: =SUM(I25:I28) -> 723 | J29: =SUM(J25:J28) -> 688 | ... P29: =SUM(P25:P28) -> 695.33333
B31: Expenses: Life & Health | O31: Total | P31: Avg
B32: Sport | C32: =SUMIFS(Table1[Amount],Table1[Type],'Final Result'!$B32,Table1[Month],'Final Result'!C$10) -> 47 | D32: =SUMIFS(Table1[Amount],Table1[Type],'Final Result'!$B32,Table1[Month],'Final Result'!D$10) -> 114 | E32: =SUMIFS(Table1[Amount],Table1[Type],'Final Result'!$B32,Table1[Month],'Final Result'!E$10) -> 121 | F32: =SUMIFS(Table1[Amount],Table1[Type],'Final Result'!$B32,Table1[Month],'Final Result'!F$10) -> 86 | G32: =SUMIFS(Table1[Amount],Table1[Type],'Final Result'!$B32,Table1[Month],'Final Result'!G$10) -> 93 | H32: =SUMIFS(Table1[Amount],Table1[Type],'Final Result'!$B32,Table1[Month],'Final Result'!H$10) -> 74 | I32: =SUMIFS(Table1[Amount],Table1[Type],'Final Result'!$B32,Table1[Month],'Final Result'!I$10) -> 54 | J32: =SUMIFS(Table1[Amount],Table1[Type],'Final Result'!$B32,Table1[Month],'Final Result'!J$10) -> 150 | ... N32: =SUMIFS(Table1[Amount],Table1[Type],'Final Result'!$B32,Table1[Month],'Final Result'!N$10) -> 148 | O32: =SUM(C32:N32) -> 1152 | P32: =AVERAGE(C32:N32) -> 96
B33: Health Insurance | C33: =SUMIFS(Table1[Amount],Table1[Type],'Final Result'!$B33,Table1[Month],'Final Result'!C$10) -> 132 | D33: =SUMIFS(Table1[Amount],Table1[Type],'Final Result'!$B33,Table1[Month],'Final Result'!D$10) -> 125 | E33: =SUMIFS(Table1[Amount],Table1[Type],'Final Result'!$B33,Table1[Month],'Final Result'!E$10) -> 112 | F33: =SUMIFS(Table1[Amount],Table1[Type],'Final Result'!$B33,Table1[Month],'Final Result'!F$10) -> 119 | G33: =SUMIFS(Table1[Amount],Table1[Type],'Final Result'!$B33,Table1[Month],'Final Result'!G$10) -> 110 | H33: =SUMIFS(Table1[Amount],Table1[Type],'Final Result'!$B33,Table1[Month],'Final Result'!H$10) -> 130 | I33: =SUMIFS(Table1[Amount],Table1[Type],'Final Result'!$B33,Table1[Month],'Final Result'!I$10) -> 131 | J33: =SUMIFS(Table1[Amount],Table1[Type],'Final Result'!$B33,Table1[Month],'Final Result'!J$10) -> 135 | ... N33: =SUMIFS(Table1[Amount],Table1[Type],'Final Result'!$B33,Table1[Month],'Final Result'!N$10) -> 131 | O33: =SUM(C33:N33) -> 1475 | P33: =AVERAGE(C33:N33) -> 122.91667
B34: Medical Expenses | C34: =SUMIFS(Table1[Amount],Table1[Type],'Final Result'!$B34,Table1[Month],'Final Result'!C$10) -> 109 | D34: =SUMIFS(Table1[Amount],Table1[Type],'Final Result'!$B34,Table1[Month],'Final Result'!D$10) -> 25 | E34: =SUMIFS(Table1[Amount],Table1[Type],'Final Result'!$B34,Table1[Month],'Final Result'!E$10) -> 190 | F34: =SUMIFS(Table1[Amount],Table1[Type],'Final Result'!$B34,Table1[Month],'Final Result'!F$10) -> 127 | G34: =SUMIFS(Table1[Amount],Table1[Type],'Final Result'!$B34,Table1[Month],'Final Result'!G$10) -> 175 | H34: =SUMIFS(Table1[Amount],Table1[Type],'Final Result'!$B34,Table1[Month],'Final Result'!H$10) -> 33 | I34: =SUMIFS(Table1[Amount],Table1[Type],'Final Result'!$B34,Table1[Month],'Final Result'!I$10) -> 30 | J34: =SUMIFS(Table1[Amount],Table1[Type],'Final Result'!$B34,Table1[Month],'Final Result'!J$10) -> 142 | ... N34: =SUMIFS(Table1[Amount],Table1[Type],'Final Result'!$B34,Table1[Month],'Final Result'!N$10) -> 238 | O34: =SUM(C34:N34) -> 1688 | P34: =AVERAGE(C34:N34) -> 140.66667
B35: Supplements | C35: =SUMIFS(Table1[Amount],Table1[Type],'Final Result'!$B35,Table1[Month],'Final Result'!C$10) -> 24 | D35: =SUMIFS(Table1[Amount],Table1[Type],'Final Result'!$B35,Table1[Month],'Final Result'!D$10) -> 48 | E35: =SUMIFS(Table1[Amount],Table1[Type],'Final Result'!$B35,Table1[Month],'Final Result'!E$10) -> 32 | F35: =SUMIFS(Table1[Amount],Table1[Type],'Final Result'!$B35,Table1[Month],'Final Result'!F$10) -> 43 | G35: =SUMIFS(Table1[Amount],Table1[Type],'Final Result'!$B35,Table1[Month],'Final Result'!G$10) -> 39 | H35: =SUMIFS(Table1[Amount],Table1[Type],'Final Result'!$B35,Table1[Month],'Final Result'!H$10) -> 27 | I35: =SUMIFS(Table1[Amount],Table1[Type],'Final Result'!$B35,Table1[Month],'Final Result'!I$10) -> 47 | J35: =SUMIFS(Table1[Amount],Table1[Type],'Final Result'!$B35,Table1[Month],'Final Result'!J$10) -> 110 | ... N35: =SUMIFS(Table1[Amount],Table1[Type],'Final Result'!$B35,Table1[Month],'Final Result'!N$10) -> 81 | O35: =SUM(C35:N35) -> 536 | P35: =AVERAGE(C35:N35) -> 44.666667
B36: Groceries | C36: =SUMIFS(Table1[Amount],Table1[Type],'Final Result'!$B36,Table1[Month],'Final Result'!C$10) -> 382 | D36: =SUMIFS(Table1[Amount],Table1[Type],'Final Result'!$B36,Table1[Month],'Final Result'!D$10) -> 371 | E36: =SUMIFS(Table1[Amount],Table1[Type],'Final Result'!$B36,Table1[Month],'Final Result'!E$10) -> 500 | F36: =SUMIFS(Table1[Amount],Table1[Type],'Final Result'!$B36,Table1[Month],'Final Result'!F$10) -> 538 | G36: =SUMIFS(Table1[Amount],Table1[Type],'Final Result'!$B36,Table1[Month],'Final Result'!G$10) -> 485 | H36: =SUMIFS(Table1[Amount],Table1[Type],'Final Result'!$B36,Table1[Month],'Final Result'!H$10) -> 539 | I36: =SUMIFS(Table1[Amount],Table1[Type],'Final Result'!$B36,Table1[Month],'Final Result'!I$10) -> 433 | J36: =SUMIFS(Table1[Amount],Table1[Type],'Final Result'!$B36,Table1[Month],'Final Result'!J$10) -> 466 | ... N36: =SUMIFS(Table1[Amount],Table1[Type],'Final Result'!$B36,Table1[Month],'Final Result'!N$10) -> 483 | O36: =SUM(C36:N36) -> 5530 | P36: =AVERAGE(C36:N36) -> 460.83333
B37: Total Life & Health | C37: =SUM(C32:C36) -> 694 | D37: =SUM(D32:D36) -> 683 | E37: =SUM(E32:E36) -> 955 | F37: =SUM(F32:F36) -> 913 | G37: =SUM(G32:G36) -> 902 | H37: =SUM(H32:H36) -> 803 | I37: =SUM(I32:I36) -> 695 | J37: =SUM(J32:J36) -> 1003 | ... P37: =SUM(P32:P36) -> 865.08333
B39: Expenses: Enjoyment | O39: Total | P39: Avg
B40: Eating Out | C40: =SUMIFS(Table1[Amount],Table1[Type],'Final Result'!$B40,Table1[Month],'Final Result'!C$10) -> 261 | D40: =SUMIFS(Table1[Amount],Table1[Type],'Final Result'!$B40,Table1[Month],'Final Result'!D$10) -> 292 | E40: =SUMIFS(Table1[Amount],Table1[Type],'Final Result'!$B40,Table1[Month],'Final Result'!E$10) -> 332 | F40: =SUMIFS(Table1[Amount],Table1[Type],'Final Result'!$B40,Table1[Month],'Final Result'!F$10) -> 212 | G40: =SUMIFS(Table1[Amount],Table1[Type],'Final Result'!$B40,Table1[Month],'Final Result'!G$10) -> 257 | H40: =SUMIFS(Table1[Amount],Table1[Type],'Final Result'!$B40,Table1[Month],'Final Result'!H$10) -> 229 | I40: =SUMIFS(Table1[Amount],Table1[Type],'Final Result'!$B40,Table1[Month],'Final Result'!I$10) -> 183 | J40: =SUMIFS(Table1[Amount],Table1[Type],'Final Result'!$B40,Table1[Month],'Final Result'!J$10) -> 241 | ... N40: =SUMIFS(Table1[Amount],Table1[Type],'Final Result'!$B40,Table1[Month],'Final Result'!N$10) -> 229 | O40: =SUM(C40:N40) -> 3112 | P40: =AVERAGE(C40:N40) -> 259.33333
B41: Entertainment | C41: =SUMIFS(Table1[Amount],Table1[Type],'Final Result'!$B41,Table1[Month],'Final Result'!C$10) -> 227 | D41: =SUMIFS(Table1[Amount],Table1[Type],'Final Result'!$B41,Table1[Month],'Final Result'!D$10) -> 154 | E41: =SUMIFS(Table1[Amount],Table1[Type],'Final Result'!$B41,Table1[Month],'Final Result'!E$10) -> 136 | F41: =SUMIFS(Table1[Amount],Table1[Type],'Final Result'!$B41,Table1[Month],'Final Result'!F$10) -> 140 | G41: =SUMIFS(Table1[Amount],Table1[Type],'Final Result'!$B41,Table1[Month],'Final Result'!G$10) -> 130 | H41: =SUMIFS(Table1[Amount],Table1[Type],'Final Result'!$B41,Table1[Month],'Final Result'!H$10) -> 285 | I41: =SUMIFS(Table1[Amount],Table1[Type],'Final Result'!$B41,Table1[Month],'Final Result'!I$10) -> 309 | J41: =SUMIFS(Table1[Amount],Table1[Type],'Final Result'!$B41,Table1[Month],'Final Result'!J$10) -> 294 | ... N41: =SUMIFS(Table1[Amount],Table1[Type],'Final Result'!$B41,Table1[Month],'Final Result'!N$10) -> 141 | O41: =SUM(C41:N41) -> 2420 | P41: =AVERAGE(C41:N41) -> 201.66667
B42: Travel | C42: =SUMIFS(Table1[Amount],Table1[Type],'Final Result'!$B42,Table1[Month],'Final Result'!C$10) -> 143 | D42: =SUMIFS(Table1[Amount],Table1[Type],'Final Result'!$B42,Table1[Month],'Final Result'!D$10) -> 240 | E42: =SUMIFS(Table1[Amount],Table1[Type],'Final Result'!$B42,Table1[Month],'Final Result'!E$10) -> 459 | F42: =SUMIFS(Table1[Amount],Table1[Type],'Final Result'!$B42,Table1[Month],'Final Result'!F$10) -> 648 | G42: =SUMIFS(Table1[Amount],Table1[Type],'Final Result'!$B42,Table1[Month],'Final Result'!G$10) -> 0 | H42: =SUMIFS(Table1[Amount],Table1[Type],'Final Result'!$B42,Table1[Month],'Final Result'!H$10) -> 0 | I42: =SUMIFS(Table1[Amount],Table1[Type],'Final Result'!$B42,Table1[Month],'Final Result'!I$10) -> 507 | J42: =SUMIFS(Table1[Amount],Table1[Type],'Final Result'!$B42,Table1[Month],'Final Result'!J$10) -> 779 | ... N42: =SUMIFS(Table1[Amount],Table1[Type],'Final Result'!$B42,Table1[Month],'Final Result'!N$10) -> 295 | O42: =SUM(C42:N42) -> 4098 | P42: =AVERAGE(C42:N42) -> 341.5
B43: Other Expenses | C43: =SUMIFS(Table1[Amount],Table1[Type],'Final Result'!$B43,Table1[Month],'Final Result'!C$10) -> 121 | D43: =SUMIFS(Table1[Amount],Table1[Type],'Final Result'!$B43,Table1[Month],'Final Result'!D$10) -> 167 | E43: =SUMIFS(Table1[Amount],Table1[Type],'Final Result'!$B43,Table1[Month],'Final Result'!E$10) -> 75 | F43: =SUMIFS(Table1[Amount],Table1[Type],'Final Result'!$B43,Table1[Month],'Final Result'!F$10) -> 136 | G43: =SUMIFS(Table1[Amount],Table1[Type],'Final Result'!$B43,Table1[Month],'Final Result'!G$10) -> 79 | H43: =SUMIFS(Table1[Amount],Table1[Type],'Final Result'!$B43,Table1[Month],'Final Result'!H$10) -> 234 | I43: =SUMIFS(Table1[Amount],Table1[Type],'Final Result'!$B43,Table1[Month],'Final Result'!I$10) -> 161 | J43: =SUMIFS(Table1[Amount],Table1[Type],'Final Result'!$B43,Table1[Month],'Final Result'!J$10) -> 119 | ... N43: =SUMIFS(Table1[Amount],Table1[Type],'Final Result'!$B43,Table1[Month],'Final Result'!N$10) -> 86 | O43: =SUM(C43:N43) -> 1785 | P43: =AVERAGE(C43:N43) -> 148.75
B44: Total Enjoyment | C44: =SUM(C40:C43) -> 752 | D44: =SUM(D40:D43) -> 853 | E44: =SUM(E40:E43) -> 1002 | F44: =SUM(F40:F43) -> 1136 | G44: =SUM(G40:G43) -> 466 | H44: =SUM(H40:H43) -> 748 | I44: =SUM(I40:I43) -> 1160 | J44: =SUM(J40:J43) -> 1433 | ... P44: =SUM(P40:P43) -> 951.25
B45: Total Expenses | C45: =SUM(C44,C37,C29,C22) -> 4431 | D45: =SUM(D44,D37,D29,D22) -> 3979 | E45: =SUM(E44,E37,E29,E22) -> 4922 | F45: =SUM(F44,F37,F29,F22) -> 5022 | G45: =SUM(G44,G37,G29,G22) -> 3845 | H45: =SUM(H44,H37,H29,H22) -> 4246 | I45: =SUM(I44,I37,I29,I22) -> 4063 | J45: =SUM(J44,J37,J29,J22) -> 5032 | ... O45: =SUM(O44,O37,O29,O22) -> 53833 | P45: =AVERAGE(C45:N45) -> 4486.0833
B47: Savings | O47: Total | P47: Avg
B48: Start Balance | C48: 10000 | D48: =C50 -> 9613 | E48: =D50 -> 10402 | F48: =E50 -> 9567 | G48: =F50 -> 9039 | H48: =G50 -> 10208 | I48: =H50 -> 11051 | J48: =I50 -> 12086 | K48: =J50 -> 12393 | ... N48: =M50 -> 13105
B49: Savings | C49: =C15-C45 -> -387 | D49: =D15-D45 -> 789 | E49: =E15-E45 -> -835 | F49: =F15-F45 -> -528 | G49: =G15-G45 -> 1169 | H49: =H15-H45 -> 843 | I49: =I15-I45 -> 1035 | J49: =J15-J45 -> 307 | ... N49: =N15-N45 -> 590 | O49: =SUM(C49:N49) -> 3695 | P49: =AVERAGE(C49:N49) -> 307.91667
...
